Internal Server Error: /api/system2/received/
Traceback (most recent call last):
  File "C:\Users\DeLL\Documents\finals_django\venv\lib\site-packages\mysql\connector\connection_cext.py", line 706, in cmd_query
    self._cmysql.query(
_mysql_connector.MySQLInterfaceError: Unknown column 'timestamp' in 'field list'

The above exception was the direct cause of the following exception:

Traceback (most recent call last):
  File "C:\Users\DeLL\Documents\finals_django\venv\lib\site-packages\django\db\backends\utils.py", line 105, in _execute
    return self.cursor.execute(sql, params)
  File "C:\Users\DeLL\Documents\finals_django\venv\lib\site-packages\mysql\connector\django\base.py", line 188, in execute
    return self.cursor.execute(query, new_args)
  File "C:\Users\DeLL\Documents\finals_django\venv\lib\site-packages\mysql\connector\cursor_cext.py", line 357, in execute
    result = self._connection.cmd_query(
  File "C:\Users\DeLL\Documents\finals_django\venv\lib\site-packages\mysql\connector\opentelemetry\context_propagation.py", line 97, in wrapper
    return method(cnx, *args, **kwargs)
  File "C:\Users\DeLL\Documents\finals_django\venv\lib\site-packages\mysql\connector\connection_cext.py", line 714, in cmd_query
    raise get_mysql_exception(
mysql.connector.errors.ProgrammingError: 1054 (42S22): Unknown column 'timestamp' in 'field list'

The above exception was the direct cause of the following exception:

Traceback (most recent call last):
  File "C:\Users\DeLL\Documents\finals_django\venv\lib\site-packages\django\core\handlers\exception.py", line 55, in inner
    response = get_response(request)
  File "C:\Users\DeLL\Documents\finals_django\venv\lib\site-packages\django\core\handlers\base.py", line 197, in _get_response
    response = wrapped_callback(request, *callback_args, **callback_kwargs)
  File "C:\Users\DeLL\Documents\finals_django\venv\lib\site-packages\django\views\decorators\csrf.py", line 65, in _view_wrapper
    return view_func(request, *args, **kwargs)
  File "C:\Users\DeLL\Documents\finals_django\venv\lib\site-packages\django\views\generic\base.py", line 104, in view
    return self.dispatch(request, *args, **kwargs)
  File "C:\Users\DeLL\Documents\finals_django\venv\lib\site-packages\rest_framework\views.py", line 509, in dispatch
    response = self.handle_exception(exc)
  File "C:\Users\DeLL\Documents\finals_django\venv\lib\site-packages\rest_framework\views.py", line 469, in handle_exception
    self.raise_uncaught_exception(exc)
  File "C:\Users\DeLL\Documents\finals_django\venv\lib\site-packages\rest_framework\views.py", line 480, in raise_uncaught_exception
    raise exc
  File "C:\Users\DeLL\Documents\finals_django\venv\lib\site-packages\rest_framework\views.py", line 506, in dispatch
    response = handler(request, *args, **kwargs)
  File "C:\Users\DeLL\Documents\finals_django\system2\views.py", line 26, in post
    received_message = ReceivedMessage.objects.create(user=user, message=message)
  File "C:\Users\DeLL\Documents\finals_django\venv\lib\site-packages\django\db\models\manager.py", line 87, in manager_method
    return getattr(self.get_queryset(), name)(*args, **kwargs)
  File "C:\Users\DeLL\Documents\finals_django\venv\lib\site-packages\django\db\models\query.py", line 679, in create
    obj.save(force_insert=True, using=self.db)
  File "C:\Users\DeLL\Documents\finals_django\venv\lib\site-packages\django\db\models\base.py", line 892, in save
    self.save_base(
  File "C:\Users\DeLL\Documents\finals_django\venv\lib\site-packages\django\db\models\base.py", line 998, in save_base
    updated = self._save_table(
  File "C:\Users\DeLL\Documents\finals_django\venv\lib\site-packages\django\db\models\base.py", line 1161, in _save_table
    results = self._do_insert(
  File "C:\Users\DeLL\Documents\finals_django\venv\lib\site-packages\django\db\models\base.py", line 1202, in _do_insert
    return manager._insert(
  File "C:\Users\DeLL\Documents\finals_django\venv\lib\site-packages\django\db\models\manager.py", line 87, in manager_method
    return getattr(self.get_queryset(), name)(*args, **kwargs)
  File "C:\Users\DeLL\Documents\finals_django\venv\lib\site-packages\django\db\models\query.py", line 1847, in _insert
    return query.get_compiler(using=using).execute_sql(returning_fields)
  File "C:\Users\DeLL\Documents\finals_django\venv\lib\site-packages\django\db\models\sql\compiler.py", line 1836, in execute_sql
    cursor.execute(sql, params)
  File "C:\Users\DeLL\Documents\finals_django\venv\lib\site-packages\django\db\backends\utils.py", line 122, in execute
    return super().execute(sql, params)
  File "C:\Users\DeLL\Documents\finals_django\venv\lib\site-packages\django\db\backends\utils.py", line 79, in execute
    return self._execute_with_wrappers(
  File "C:\Users\DeLL\Documents\finals_django\venv\lib\site-packages\django\db\backends\utils.py", line 92, in _execute_with_wrappers
    return executor(sql, params, many, context)
  File "C:\Users\DeLL\Documents\finals_django\venv\lib\site-packages\django\db\backends\utils.py", line 100, in _execute
    with self.db.wrap_database_errors:
  File "C:\Users\DeLL\Documents\finals_django\venv\lib\site-packages\django\db\utils.py", line 91, in __exit__
    raise dj_exc_value.with_traceback(traceback) from exc_value
  File "C:\Users\DeLL\Documents\finals_django\venv\lib\site-packages\django\db\backends\utils.py", line 105, in _execute
    return self.cursor.execute(sql, params)
  File "C:\Users\DeLL\Documents\finals_django\venv\lib\site-packages\mysql\connector\django\base.py", line 188, in execute
    return self.cursor.execute(query, new_args)
  File "C:\Users\DeLL\Documents\finals_django\venv\lib\site-packages\mysql\connector\cursor_cext.py", line 357, in execute
    result = self._connection.cmd_query(
  File "C:\Users\DeLL\Documents\finals_django\venv\lib\site-packages\mysql\connector\opentelemetry\context_propagation.py", line 97, in wrapper
    return method(cnx, *args, **kwargs)
  File "C:\Users\DeLL\Documents\finals_django\venv\lib\site-packages\mysql\connector\connection_cext.py", line 714, in cmd_query
    raise get_mysql_exception(
django.db.utils.ProgrammingError: (1054, "1054 (42S22): Unknown column 'timestamp' in 'field list'", '42S22')
"POST /api/system2/received/ HTTP/1.1" 500 225648
